Workbook

Sheet data
A1: compressor | B1: data_source | C1: tag | D1: temperature_in | E1: pressure_in | F1: pressure_impeller_out | G1: pressure_out | H1: pressure_ratio | I1: angular_speed | J1: mass_flow | K1: mass_flow_eq | L1: isentropic_work_eq_plot | M1: isentropic_work_eq_plot2
A2: - | B2: - | C2: - | D2: degC | E2: bar | F2: bar | G2: bar | H2: - | I2: RPM | J2: kg/s | K2: kg/s | L2: kJ/kg | M2: kJ/kg
A3: BMPC | B3: =data_imperial_units!B3 -> EXP | C3: =data_imperial_units!C3 -> varSpeed-constTempPressure-1 | D3: =(data_imperial_units!D3 - 32) * 5/9 -> 35.833333 | E3: =data_imperial_units!E3*0.0689476 -> 92.80347 | G3: =data_imperial_units!G3*0.0689476 -> 137.48151 | H3: =data_imperial_units!H3 -> 1.4814264 | I3: =data_imperial_units!I3 -> 54175 | J3: =data_imperial_units!J3*0.453592 -> 4.4633453
A4: BMPC | B4: =data_imperial_units!B4 -> EXP | C4: =data_imperial_units!C4 -> varSpeed-constTempPressure-1 | D4: =(data_imperial_units!D4 - 32) * 5/9 -> 35.777778 | E4: =data_imperial_units!E4*0.0689476 -> 92.941365 | G4: =data_imperial_units!G4*0.0689476 -> 134.79256 | H4: =data_imperial_units!H4 -> 1.4502967 | I4: =data_imperial_units!I4 -> 52400 | J4: =data_imperial_units!J4*0.453592 -> 4.3227318
A5: BMPC | B5: =data_imperial_units!B5 -> EXP | C5: =data_imperial_units!C5 -> varSpeed-constTempPressure-1 | D5: =(data_imperial_units!D5 - 32) * 5/9 -> 35.611111 | E5: =data_imperial_units!E5*0.0689476 -> 92.596627 | G5: =data_imperial_units!G5*0.0689476 -> 133.06887 | H5: =data_imperial_units!H5 -> 1.4370812 | I5: =data_imperial_units!I5 -> 50885 | J5: =data_imperial_units!J5*0.453592 -> 4.2184056
A6: BMPC | B6: =data_imperial_units!B6 -> EXP | C6: =data_imperial_units!C6 -> varSpeed-constTempPressure-1 | D6: =(data_imperial_units!D6 - 32) * 5/9 -> 35.777778 | E6: =data_imperial_units!E6*0.0689476 -> 93.35505 | G6: =data_imperial_units!G6*0.0689476 -> 129.48359 | H6: =data_imperial_units!H6 -> 1.3870015 | I6: =data_imperial_units!I6 -> 48750 | J6: =data_imperial_units!J6*0.453592 -> 4.027897
A7: BMPC | B7: =data_imperial_units!B7 -> EXP | C7: =data_imperial_units!C7 -> varSpeed-constTempPressure-1 | D7: =(data_imperial_units!D7 - 32) * 5/9 -> 35.777778 | E7: =data_imperial_units!E7*0.0689476 -> 93.35505 | G7: =data_imperial_units!G7*0.0689476 -> 127.20832 | H7: =data_imperial_units!H7 -> 1.3626292 | I7: =data_imperial_units!I7 -> 47160 | J7: =data_imperial_units!J7*0.453592 -> 3.9235708
A8: BMPC | B8: =data_imperial_units!B8 -> EXP | C8: =data_imperial_units!C8 -> varSpeed-constTempPressure-1 | D8: =(data_imperial_units!D8 - 32) * 5/9 -> 35.777778 | E8: =data_imperial_units!E8*0.0689476 -> 93.286103 | G8: =data_imperial_units!G8*0.0689476 -> 124.03673 | H8: =data_imperial_units!H8 -> 1.3296378 | I8: =data_imperial_units!I8 -> 45160 | J8: =data_imperial_units!J8*0.453592 -> 3.7693495
A9: BMPC | B9: =data_imperial_units!B9 -> EXP | C9: =data_imperial_units!C9 -> varSpeed-constTempPressure-1 | D9: =(data_imperial_units!D9 - 32) * 5/9 -> 35.777778 | E9: =data_imperial_units!E9*0.0689476 -> 92.872417 | G9: =data_imperial_units!G9*0.0689476 -> 118.58987 | H9: =data_imperial_units!H9 -> 1.2769117 | I9: =data_imperial_units!I9 -> 41450 | J9: =data_imperial_units!J9*0.453592 -> 3.3747245
A10: BMPC | B10: =data_imperial_units!B10 -> EXP | C10: =data_imperial_units!C10 -> varSpeed-constTempPressure-2 | D10: =(data_imperial_units!D10 - 32) * 5/9 -> 35.833333 | E10: =data_imperial_units!E10*0.0689476 -> 92.010774 | F10: =data_imperial_units!F10*0.0689476 -> 122.41223 | G10: =data_imperial_units!G10*0.0689476 -> 133.54061 | H10: =data_imperial_units!H10 -> 1.4513585 | I10: 51700 | K10: =data_imperial_units!K10*0.453592 -> 4.1184708 | L10: =data_imperial_units!L10*2.326 -> 4.6414512
A11: BMPC | B11: =data_imperial_units!B11 -> EXP | C11: =data_imperial_units!C11 -> varSpeed-constTempPressure-2 | D11: =(data_imperial_units!D11 - 32) * 5/9 -> 35.777778 | E11: =data_imperial_units!E11*0.0689476 -> 92.010774 | F11: =data_imperial_units!F11*0.0689476 -> 120.31558 | G11: =data_imperial_units!G11*0.0689476 -> 130.87948 | H11: =data_imperial_units!H11 -> 1.4224365 | I11: 50150 | K11: =data_imperial_units!K11*0.453592 -> 3.9883567 | L11: =data_imperial_units!L11*2.326 -> 4.3645465
A12: BMPC | B12: =data_imperial_units!B12 -> EXP | C12: =data_imperial_units!C12 -> varSpeed-constTempPressure-2 | D12: =(data_imperial_units!D12 - 32) * 5/9 -> 35.611111 | E12: =data_imperial_units!E12*0.0689476 -> 91.930133 | F12: =data_imperial_units!F12*0.0689476 -> 118.78341 | G12: =data_imperial_units!G12*0.0689476 -> 128.37962 | H12: =data_imperial_units!H12 -> 1.3964912 | I12: 48600 | K12: =data_imperial_units!K12*0.453592 -> 3.8640256 | L12: =data_imperial_units!L12*2.326 -> 4.1140136
A13: BMPC | B13: =data_imperial_units!B13 -> EXP | C13: =data_imperial_units!C13 -> varSpeed-constTempPressure-2 | D13: =(data_imperial_units!D13 - 32) * 5/9 -> 35.777778 | E13: =data_imperial_units!E13*0.0689476 -> 91.849493 | F13: =data_imperial_units!F13*0.0689476 -> 117.08996 | G13: =data_imperial_units!G13*0.0689476 -> 125.87977 | H13: =data_imperial_units!H13 -> 1.3705004 | I13: 47050 | K13: =data_imperial_units!K13*0.453592 -> 3.76138 | L13: =data_imperial_units!L13*2.326 -> 3.8239229
A14: BMPC | B14: =data_imperial_units!B14 -> EXP | C14: =data_imperial_units!C14 -> varSpeed-constTempPressure-2 | D14: =(data_imperial_units!D14 - 32) * 5/9 -> 35.777778 | E14: =data_imperial_units!E14*0.0689476 -> 91.688212 | F14: =data_imperial_units!F14*0.0689476 -> 115.23523 | G14: =data_imperial_units!G14*0.0689476 -> 123.5412 | H14: =data_imperial_units!H14 -> 1.3474055 | I14: 45500 | K14: =data_imperial_units!K14*0.453592 -> 3.6269289 | L14: =data_imperial_units!L14*2.326 -> 3.586576
A15: BMPC | B15: =data_imperial_units!B15 -> EXP | C15: =data_imperial_units!C15 -> varSpeed-constTempPressure-2 | D15: =(data_imperial_units!D15 - 32) * 5/9 -> 35.777778 | E15: =data_imperial_units!E15*0.0689476 -> 91.688212 | F15: =data_imperial_units!F15*0.0689476 -> 113.62242 | G15: =data_imperial_units!G15*0.0689476 -> 121.28326 | H15: =data_imperial_units!H15 -> 1.3227792 | I15: 43950 | K15: =data_imperial_units!K15*0.453592 -> 3.4881406 | L15: =data_imperial_units!L15*2.326 -> 3.349229
A16: BMPC | B16: =data_imperial_units!B16 -> EXP | C16: =data_imperial_units!C16 -> varSpeed-constTempPressure-2 | D16: =(data_imperial_units!D16 - 32) * 5/9 -> 35.777778 | E16: =data_imperial_units!E16*0.0689476 -> 90.962448 | F16: =data_imperial_units!F16*0.0689476 -> 111.28385 | G16: =data_imperial_units!G16*0.0689476 -> 118.38021 | H16: =data_imperial_units!H16 -> 1.3014184 | I16: 42400 | K16: =data_imperial_units!K16*0.453592 -> 3.2973066 | L16: =data_imperial_units!L16*2.326 -> 3.0855102
A17: BMPC | B17: =data_imperial_units!B17 -> EXP | C17: =data_imperial_units!C17 -> varPressure-constTempSpeed | D17: =(data_imperial_units!D17 - 32) * 5/9 -> 35.555556 | E17: =data_imperial_units!E17*0.0689476 -> 83.09277 | F17: =data_imperial_units!F17*0.0689476 -> 105.07841 | G17: =data_imperial_units!G17*0.0689476 -> 112.35306 | H17: =data_imperial_units!H17 -> 1.3521401 | I17: =data_imperial_units!I17 -> 47000 | K17: =data_imperial_units!K17*0.453592 -> 2.9561187 | L17: =data_imperial_units!L17*2.326 -> 3.2041837 | M17: =data_imperial_units!M17*2.326 -> 4.1713996
A18: BMPC | B18: =data_imperial_units!B18 -> EXP | C18: =data_imperial_units!C18 -> varPressure-constTempSpeed | D18: =(data_imperial_units!D18 - 32) * 5/9 -> 35.555556 | E18: =data_imperial_units!E18*0.0689476 -> 84.466872 | F18: =data_imperial_units!F18*0.0689476 -> 107.50329 | G18: =data_imperial_units!G18*0.0689476 -> 115.34376 | H18: =data_imperial_units!H18 -> 1.3655502 | I18: =data_imperial_units!I18 -> 47000 | K18: =data_imperial_units!K18*0.453592 -> 3.2336953 | L18: =data_imperial_units!L18*2.326 -> 3.4415306 | M18: =data_imperial_units!M18*2.326 -> 4.4883208
A19: BMPC | B19: =data_imperial_units!B19 -> EXP | C19: =data_imperial_units!C19 -> varPressure-constTempSpeed | D19: =(data_imperial_units!D19 - 32) * 5/9 -> 35.555556 | E19: =data_imperial_units!E19*0.0689476 -> 86.245122 | F19: =data_imperial_units!F19*0.0689476 -> 109.84735 | G19: =data_imperial_units!G19*0.0689476 -> 118.17279 | H19: =data_imperial_units!H19 -> 1.3701968 | I19: =data_imperial_units!I19 -> 47000 | K19: =data_imperial_units!K19*0.453592 -> 3.4679006 | L19: =data_imperial_units!L19*2.326 -> 3.586576 | M19: =data_imperial_units!M19*2.326 -> 4.7063388
A20: BMPC | B20: =data_imperial_units!B20 -> EXP | C20: =data_imperial_units!C20 -> varPressure-constTempSpeed | D20: =(data_imperial_units!D20 - 32) * 5/9 -> 35.555556 | E20: =data_imperial_units!E20*0.0689476 -> 87.861713 | F20: =data_imperial_units!F20*0.0689476 -> 112.11058 | G20: =data_imperial_units!G20*0.0689476 -> 120.84017 | H20: =data_imperial_units!H20 -> 1.375345 | I20: =data_imperial_units!I20 -> 47000 | K20: =data_imperial_units!K20*0.453592 -> 3.6225917 | L20: =data_imperial_units!L20*2.326 -> 3.7052494 | M20: =data_imperial_units!M20*2.326 -> 4.8450891
A21: BMPC | B21: =data_imperial_units!B21 -> EXP | C21: =data_imperial_units!C21 -> varPressure-constTempSpeed | D21: =(data_imperial_units!D21 - 32) * 5/9 -> 35.555556 | E21: =data_imperial_units!E21*0.0689476 -> 89.639963 | F21: =data_imperial_units!F21*0.0689476 -> 114.21214 | G21: =data_imperial_units!G21*0.0689476 -> 123.02256 | H21: =data_imperial_units!H21 -> 1.3724076 | I21: =data_imperial_units!I21 -> 47000 | K21: =data_imperial_units!K21*0.453592 -> 3.716563 | L21: =data_imperial_units!L21*2.326 -> 3.7316213 | M21: =data_imperial_units!M21*2.326 -> 4.9243993
A22: BMPC | B22: =data_imperial_units!B22 -> EXP | C22: =data_imperial_units!C22 -> varPressure-constTempSpeed | D22: =(data_imperial_units!D22 - 32) * 5/9 -> 35.555556 | E22: =data_imperial_units!E22*0.0689476 -> 91.256554 | F22: =data_imperial_units!F22*0.0689476 -> 116.63703 | G22: =data_imperial_units!G22*0.0689476 -> 125.52828 | H22: =data_imperial_units!H22 -> 1.3755536 | I22: =data_imperial_units!I22 -> 47000 | K22: =data_imperial_units!K22*0.453592 -> 3.7960771 | L22: =data_imperial_units!L22*2.326 -> 3.7843651 | M22: =data_imperial_units!M22*2.326 -> 5.0036456
A23: BMPC | B23: =data_imperial_units!B23 -> EXP | C23: =data_imperial_units!C23 -> varPressure-constTempSpeed | D23: =(data_imperial_units!D23 - 32) * 5/9 -> 35.555556 | E23: =data_imperial_units!E23*0.0689476 -> 93.115633 | F23: =data_imperial_units!F23*0.0689476 -> 118.65777 | G23: =data_imperial_units!G23*0.0689476 -> 127.95317 | H23: =data_imperial_units!H23 -> 1.3741319 | I23: =data_imperial_units!I23 -> 47000 | K23: =data_imperial_units!K23*0.453592 -> 3.8726998 | L23: =data_imperial_units!L23*2.326 -> 3.797551 | M23: =data_imperial_units!M23*2.326 -> 5.0927417
A24: BMPC | B24: =data_imperial_units!B24 -> EXP | C24: =data_imperial_units!C24 -> varPressure-constTempSpeed | D24: =(data_imperial_units!D24 - 32) * 5/9 -> 35.555556 | E24: =data_imperial_units!E24*0.0689476 -> 94.732224 | F24: =data_imperial_units!F24*0.0689476 -> 120.59768 | G24: =data_imperial_units!G24*0.0689476 -> 129.73142 | H24: =data_imperial_units!H24 -> 1.3694539 | I24: =data_imperial_units!I24 -> 47000 | K24: =data_imperial_units!K24*0.453592 -> 3.8871569 | L24: =data_imperial_units!L24*2.326 -> 3.8239229 | M24: =data_imperial_units!M24*2.326 -> 5.1026982
A25: BMPC | B25: =data_imperial_units!B25 -> EXP | C25: =data_imperial_units!C25 -> varPressure-constTempSpeed | D25: =(data_imperial_units!D25 - 32) * 5/9 -> 35.555556 | E25: =data_imperial_units!E25*0.0689476 -> 96.348815 | F25: =data_imperial_units!F25*0.0689476 -> 122.86091 | G25: =data_imperial_units!G25*0.0689476 -> 131.75215 | H25: =data_imperial_units!H25 -> 1.3674497 | I25: =data_imperial_units!I25 -> 47000 | K25: =data_imperial_units!K25*0.453592 -> 3.8929398 | L25: =data_imperial_units!L25*2.326 -> 3.810737 | M25: =data_imperial_units!M25*2.326 -> 5.0533318
A26: BMPC | B26: =data_imperial_units!B26 -> EXP | C26: =data_imperial_units!C26 -> varTemp-constPressureSpeed | D26: =(data_imperial_units!D26 - 32) * 5/9 -> 31.107185 | E26: =data_imperial_units!E26*0.0689476 -> 92.145679 | F26: =data_imperial_units!F26*0.0689476 -> 120.35519 | G26: =data_imperial_units!G26*0.0689476 -> 131.50967 | H26: =data_imperial_units!H26 -> 1.427193 | I26: =data_imperial_units!I26 -> 48628.021 | K26: =data_imperial_units!K26*0.453592 -> 4.5608585 | L26: =data_imperial_units!L26*2.326 -> 4.5623356
A27: BMPC | B27: =data_imperial_units!B27 -> EXP | C27: =data_imperial_units!C27 -> varTemp-constPressureSpeed | D27: =(data_imperial_units!D27 - 32) * 5/9 -> 32.249706 | E27: =data_imperial_units!E27*0.0689476 -> 92.064849 | F27: =data_imperial_units!F27*0.0689476 -> 119.87021 | G27: =data_imperial_units!G27*0.0689476 -> 130.7822 | H27: =data_imperial_units!H27 -> 1.4205443 | I27: =data_imperial_units!I27 -> 48630.965 | K27: =data_imperial_units!K27*0.453592 -> 4.4336359 | L27: =data_imperial_units!L27*2.326 -> 4.4568481
A28: BMPC | B28: =data_imperial_units!B28 -> EXP | C28: =data_imperial_units!C28 -> varTemp-constPressureSpeed | D28: =(data_imperial_units!D28 - 32) * 5/9 -> 33.35689 | E28: =data_imperial_units!E28*0.0689476 -> 92.145679 | F28: =data_imperial_units!F28*0.0689476 -> 119.46606 | G28: =data_imperial_units!G28*0.0689476 -> 130.21639 | H28: =data_imperial_units!H28 -> 1.4131579 | I28: =data_imperial_units!I28 -> 48633.786 | K28: =data_imperial_units!K28*0.453592 -> 4.2890648 | L28: =data_imperial_units!L28*2.326 -> 4.3249887
A29: BMPC | B29: =data_imperial_units!B29 -> EXP | C29: =data_imperial_units!C29 -> varTemp-constPressureSpeed | D29: =(data_imperial_units!D29 - 32) * 5/9 -> 34.464075 | E29: =data_imperial_units!E29*0.0689476 -> 92.145679 | F29: =data_imperial_units!F29*0.0689476 -> 119.46606 | G29: =data_imperial_units!G29*0.0689476 -> 129.56976 | H29: =data_imperial_units!H29 -> 1.4061404 | I29: =data_imperial_units!I29 -> 48585.602 | K29: =data_imperial_units!K29*0.453592 -> 4.1271451 | L29: =data_imperial_units!L29*2.326 -> 4.1931293
A30: BMPC | B30: =data_imperial_units!B30 -> EXP | C30: =data_imperial_units!C30 -> varTemp-constPressureSpeed | D30: =(data_imperial_units!D30 - 32) * 5/9 -> 35.559482 | E30: =data_imperial_units!E30*0.0689476 -> 91.90319 | F30: =data_imperial_units!F30*0.0689476 -> 118.57694 | G30: =data_imperial_units!G30*0.0689476 -> 128.35731 | H30: =data_imperial_units!H30 -> 1.3966579 | I30: =data_imperial_units!I30 -> 48588.393 | K30: =data_imperial_units!K30*0.453592 -> 3.9160712 | L30: =data_imperial_units!L30*2.326 -> 4.0744558
A31: BMPC | B31: =data_imperial_units!B31 -> EXP | C31: =data_imperial_units!C31 -> varTemp-constPressureSpeed | D31: =(data_imperial_units!D31 - 32) * 5/9 -> 36.690224 | E31: =data_imperial_units!E31*0.0689476 -> 91.741531 | F31: =data_imperial_units!F31*0.0689476 -> 117.84947 | G31: =data_imperial_units!G31*0.0689476 -> 127.2257 | H31: =data_imperial_units!H31 -> 1.3867841 | I31: =data_imperial_units!I31 -> 48591.276 | K31: =data_imperial_units!K31*0.453592 -> 3.7021059 | L31: =data_imperial_units!L31*2.326 -> 3.8766667
A32: BMPC | B32: =data_imperial_units!B32 -> EXP | C32: =data_imperial_units!C32 -> varTemp-constPressureSpeed | D32: =(data_imperial_units!D32 - 32) * 5/9 -> 37.820966 | E32: =data_imperial_units!E32*0.0689476 -> 91.822361 | F32: =data_imperial_units!F32*0.0689476 -> 117.3645 | G32: =data_imperial_units!G32*0.0689476 -> 126.01326 | H32: =data_imperial_units!H32 -> 1.3723592 | I32: =data_imperial_units!I32 -> 48670.683 | K32: =data_imperial_units!K32*0.453592 -> 3.4534435 | L32: =data_imperial_units!L32*2.326 -> 3.6788776
A33: BMPC | B33: =data_imperial_units!B33 -> EXP | C33: =data_imperial_units!C33 -> varTempPressure-constSpeedMass | D33: =(data_imperial_units!D33 - 32) * 5/9 -> 32.426384 | E33: =data_imperial_units!E33*0.0689476 -> 83.254429 | F33: =data_imperial_units!F33*0.0689476 -> 109.76652 | G33: =data_imperial_units!G33*0.0689476 -> 120.03187 | H33: =data_imperial_units!H33 -> 1.4417476 | I33: =data_imperial_units!I33 -> 48656.908 | K33: =data_imperial_units!K33*0.453592 -> 4.3440018 | L33: =data_imperial_units!L33*2.326 -> 4.4304762 | M33: =data_imperial_units!M33*2.326 -> 5.4530634
A34: BMPC | B34: =data_imperial_units!B34 -> EXP | C34: =data_imperial_units!C34 -> varTempPressure-constSpeedMass | D34: =(data_imperial_units!D34 - 32) * 5/9 -> 33.486455 | E34: =data_imperial_units!E34*0.0689476 -> 85.840974 | F34: =data_imperial_units!F34*0.0689476 -> 112.35306 | G34: =data_imperial_units!G34*0.0689476 -> 122.53759 | H34: =data_imperial_units!H34 -> 1.4274953 | I34: =data_imperial_units!I34 -> 48685.157 | K34: =data_imperial_units!K34*0.453592 -> 4.2254534 | L34: =data_imperial_units!L34*2.326 -> 4.2722449 | M34: =data_imperial_units!M34*2.326 -> 5.339851
A35: BMPC | B35: =data_imperial_units!B35 -> EXP | C35: =data_imperial_units!C35 -> varTempPressure-constSpeedMass | D35: =(data_imperial_units!D35 - 32) * 5/9 -> 34.605418 | E35: =data_imperial_units!E35*0.0689476 -> 88.34669 | F35: =data_imperial_units!F35*0.0689476 -> 114.93961 | G35: =data_imperial_units!G35*0.0689476 -> 124.96247 | H35: =data_imperial_units!H35 -> 1.4144556 | I35: =data_imperial_units!I35 -> 48687.948 | K35: =data_imperial_units!K35*0.453592 -> 4.1011223 | L35: =data_imperial_units!L35*2.326 -> 4.1140136 | M35: =data_imperial_units!M35*2.326 -> 5.1700324
A36: BMPC | B36: =data_imperial_units!B36 -> EXP | C36: =data_imperial_units!C36 -> varTempPressure-constSpeedMass | D36: =(data_imperial_units!D36 - 32) * 5/9 -> 35.724382 | E36: =data_imperial_units!E36*0.0689476 -> 90.771577 | F36: =data_imperial_units!F36*0.0689476 -> 117.52616 | G36: =data_imperial_units!G36*0.0689476 -> 127.30653 | H36: =data_imperial_units!H36 -> 1.4024933 | I36: =data_imperial_units!I36 -> 48639.794 | K36: =data_imperial_units!K36*0.453592 -> 3.9710082 | L36: =data_imperial_units!L36*2.326 -> 3.9557823 | M36: =data_imperial_units!M36*2.326 -> 5.0379513
A37: BMPC | B37: =data_imperial_units!B37 -> EXP | C37: =data_imperial_units!C37 -> varTempPressure-constSpeedMass | D37: =(data_imperial_units!D37 - 32) * 5/9 -> 36.796231 | E37: =data_imperial_units!E37*0.0689476 -> 93.519781 | F37: =data_imperial_units!F37*0.0689476 -> 120.59768 | G37: =data_imperial_units!G37*0.0689476 -> 130.13556 | H37: =data_imperial_units!H37 -> 1.3915298 | I37: =data_imperial_units!I37 -> 48642.616 | K37: =data_imperial_units!K37*0.453592 -> 3.8553513 | L37: =data_imperial_units!L37*2.326 -> 3.9030385 | M37: =data_imperial_units!M37*2.326 -> 4.9436077
A38: BMPC | B38: =data_imperial_units!B38 -> EXP | C38: =data_imperial_units!C38 -> varTempPressure-constSpeedMass | D38: =(data_imperial_units!D38 - 32) * 5/9 -> 37.938751 | E38: =data_imperial_units!E38*0.0689476 -> 95.944667 | F38: =data_imperial_units!F38*0.0689476 -> 123.26505 | G38: =data_imperial_units!G38*0.0689476 -> 132.56045 | H38: =data_imperial_units!H38 -> 1.3816344 | I38: =data_imperial_units!I38 -> 48645.499 | K38: =data_imperial_units!K38*0.453592 -> 3.7425858 | L38: =data_imperial_units!L38*2.326 -> 3.797551 | M38: =data_imperial_units!M38*2.326 -> 4.8115265
A39: BMPC | B39: =data_imperial_units!B39 -> EXP | C39: =data_imperial_units!C39 -> varTempPressure-constSpeedMass | D39: =(data_imperial_units!D39 - 32) * 5/9 -> 39.045936 | E39: =data_imperial_units!E39*0.0689476 -> 98.450383 | F39: =data_imperial_units!F39*0.0689476 -> 125.93243 | G39: =data_imperial_units!G39*0.0689476 -> 134.98534 | H39: =data_imperial_units!H39 -> 1.3711002 | I39: =data_imperial_units!I39 -> 48673.809 | K39: =data_imperial_units!K39*0.453592 -> 3.6327117 | L39: =data_imperial_units!L39*2.326 -> 3.6920635 | M39: =data_imperial_units!M39*2.326 -> 4.7171829

Sheet data_imperial_units
A1: compressor | B1: data_source | C1: tag | D1: T_in | E1: p_in | F1: pressure_impeller_out | G1: p_out | H1: pressure_ratio | I1: angular_speed | J1: mass_flow_eq | K1: mass_flow_eq | L1: isentropic_work_eq | M1: isentropic_work_eq_bis
A2: - | B2: - | C2: - | D2: degF | E2: psia | F2: psia | G2: psia | H2: - | I2: RPM | J2: lbm/s | K2: lbm/s | L2: btu/lbm | M2: btu/lbm
A3: IST | B3: EXP | C3: varSpeed-constTempPressure-1 | D3: 96.5 | E3: 1346 | G3: 1994 | H3: =G3/E3 -> 1.4814264 | I3: 54175 | J3: 9.84
A4: IST | B4: EXP | C4: varSpeed-constTempPressure-1 | D4: 96.4 | E4: 1348 | G4: 1955 | H4: =G4/E4 -> 1.4502967 | I4: 52400 | J4: 9.53
A5: IST | B5: EXP | C5: varSpeed-constTempPressure-1 | D5: 96.1 | E5: 1343 | G5: 1930 | H5: =G5/E5 -> 1.4370812 | I5: 50885 | J5: 9.3
A6: IST | B6: EXP | C6: varSpeed-constTempPressure-1 | D6: 96.4 | E6: 1354 | G6: 1878 | H6: =G6/E6 -> 1.3870015 | I6: 48750 | J6: 8.88
A7: IST | B7: EXP | C7: varSpeed-constTempPressure-1 | D7: 96.4 | E7: 1354 | G7: 1845 | H7: =G7/E7 -> 1.3626292 | I7: 47160 | J7: 8.65
A8: IST | B8: EXP | C8: varSpeed-constTempPressure-1 | D8: 96.4 | E8: 1353 | G8: 1799 | H8: =G8/E8 -> 1.3296378 | I8: 45160 | J8: 8.31
A9: IST | B9: EXP | C9: varSpeed-constTempPressure-1 | D9: 96.4 | E9: 1347 | G9: 1720 | H9: =G9/E9 -> 1.2769117 | I9: 41450 | J9: 7.44
A10: IST | B10: EXP | C10: varSpeed-constTempPressure-2 | D10: 96.5 | E10: 1334.5029 | F10: 1775.4386 | G10: 1936.8421 | H10: =G10/E10 -> 1.4513585 | I10: 54175 | K10: 9.0796813 | L10: 1.9954649
A11: IST | B11: EXP | C11: varSpeed-constTempPressure-2 | D11: 96.4 | E11: 1334.5029 | F11: 1745.0292 | G11: 1898.2456 | H11: =G11/E11 -> 1.4224365 | I11: 52400 | K11: 8.7928287 | L11: 1.8764172
A12: IST | B12: EXP | C12: varSpeed-constTempPressure-2 | D12: 96.1 | E12: 1333.3333 | F12: 1722.807 | G12: 1861.9883 | H12: =G12/E12 -> 1.3964912 | I12: 50855 | K12: 8.5187251 | L12: 1.7687075
A13: IST | B13: EXP | C13: varSpeed-constTempPressure-2 | D13: 96.4 | E13: 1332.1637 | F13: 1698.2456 | G13: 1825.731 | H13: =G13/E13 -> 1.3705004 | I13: 48750 | K13: 8.2924303 | L13: 1.6439909
A14: IST | B14: EXP | C14: varSpeed-constTempPressure-2 | D14: 96.4 | E14: 1329.8246 | F14: 1671.345 | G14: 1791.8129 | H14: =G14/E14 -> 1.3474055 | I14: 47160 | K14: 7.9960159 | L14: 1.5419501
A15: IST | B15: EXP | C15: varSpeed-constTempPressure-2 | D15: 96.4 | E15: 1329.8246 | F15: 1647.9532 | G15: 1759.0643 | H15: =G15/E15 -> 1.3227792 | I15: 45160 | K15: 7.6900398 | L15: 1.4399093
A16: IST | B16: EXP | C16: varSpeed-constTempPressure-2 | D16: 96.4 | E16: 1319.2982 | F16: 1614.0351 | G16: 1716.9591 | H16: =G16/E16 -> 1.3014184 | I16: 41450 | K16: 7.2693227 | L16: 1.3265306
A17: IST | B17: EXP | C17: varPressure-constTempSpeed | D17: 96 | E17: 1205.1583 | F17: 1524.0328 | G17: 1629.5428 | H17: =G17/E17 -> 1.3521401 | I17: 47000 | K17: 6.5171315 | L17: 1.377551 | M17: 1.793379
A18: IST | B18: EXP | C18: varPressure-constTempSpeed | D18: 96 | E18: 1225.0879 | F18: 1559.2028 | G18: 1672.9191 | H18: =G18/E18 -> 1.3655502 | I18: 47000 | K18: 7.1290837 | L18: 1.4795918 | M18: 1.9296306
A19: IST | B19: EXP | C19: varPressure-constTempSpeed | D19: 96 | E19: 1250.8792 | F19: 1593.2005 | G19: 1713.9508 | H19: =G19/E19 -> 1.3701968 | I19: 47000 | K19: 7.6454183 | L19: 1.5419501 | M19: 2.0233615
A20: IST | B20: EXP | C20: varPressure-constTempSpeed | D20: 96 | E20: 1274.3259 | F20: 1626.0258 | G20: 1752.6377 | H20: =G20/E20 -> 1.375345 | I20: 47000 | K20: 7.9864542 | L20: 1.5929705 | M20: 2.0830134
A21: IST | B21: EXP | C21: varPressure-constTempSpeed | D21: 96 | E21: 1300.1172 | F21: 1656.5064 | G21: 1784.2907 | H21: =G21/E21 -> 1.3724076 | I21: 47000 | K21: 8.1936255 | L21: 1.6043084 | M21: 2.1171106
A22: IST | B22: EXP | C22: varPressure-constTempSpeed | D22: 96 | E22: 1323.5639 | F22: 1691.6764 | G22: 1820.6331 | H22: =G22/E22 -> 1.3755536 | I22: 47000 | K22: 8.3689243 | L22: 1.6269841 | M22: 2.1511804
A23: IST | B23: EXP | C23: varPressure-constTempSpeed | D23: 96 | E23: 1350.5275 | F23: 1720.9848 | G23: 1855.803 | H23: =G23/E23 -> 1.3741319 | I23: 47000 | K23: 8.5378486 | L23: 1.6326531 | M23: 2.1894848
A24: IST | B24: EXP | C24: varPressure-constTempSpeed | D24: 96 | E24: 1373.9742 | F24: 1749.1208 | G24: 1881.5944 | H24: =G24/E24 -> 1.3694539 | I24: 47000 | K24: 8.5697211 | L24: 1.6439909 | M24: 2.1937653
A25: IST | B25: EXP | C25: varPressure-constTempSpeed | D25: 96 | E25: 1397.4209 | F25: 1781.9461 | G25: 1910.9027 | H25: =G25/E25 -> 1.3674497 | I25: 47000 | K25: 8.5824701 | L25: 1.638322 | M25: 2.1725416
A26: IST | B26: EXP | C26: varTemp-constPressureSpeed | D26: 87.992933 | E26: 1336.4596 | F26: 1745.6038 | G26: 1907.3857 | H26: =G26/E26 -> 1.427193 | I26: 48628.021 | K26: 10.05498 | L26: 1.9614512
A27: IST | B27: EXP | C27: varTemp-constPressureSpeed | D27: 90.04947 | E27: 1335.2872 | F27: 1738.5698 | G27: 1896.8347 | H27: =G27/E27 -> 1.4205443 | I27: 48630.965 | K27: 9.774502 | L27: 1.9160998
A28: IST | B28: EXP | C28: varTemp-constPressureSpeed | D28: 92.042403 | E28: 1336.4596 | F28: 1732.7081 | G28: 1888.6284 | H28: =G28/E28 -> 1.4131579 | I28: 48633.786 | K28: 9.4557769 | L28: 1.8594104
A29: IST | B29: EXP | C29: varTemp-constPressureSpeed | D29: 94.035336 | E29: 1336.4596 | F29: 1732.7081 | G29: 1879.2497 | H29: =G29/E29 -> 1.4061404 | I29: 48585.602 | K29: 9.0988048 | L29: 1.8027211
A30: IST | B30: EXP | C30: varTemp-constPressureSpeed | D30: 96.007067 | E30: 1332.9426 | F30: 1719.8124 | G30: 1861.6647 | H30: =G30/E30 -> 1.3966579 | I30: 48588.393 | K30: 8.6334661 | L30: 1.7517007
A31: IST | B31: EXP | C31: varTemp-constPressureSpeed | D31: 98.042403 | E31: 1330.5979 | F31: 1709.2614 | G31: 1845.2521 | H31: =G31/E31 -> 1.3867841 | I31: 48591.276 | K31: 8.161753 | L31: 1.6666667
A32: IST | B32: EXP | C32: varTemp-constPressureSpeed | D32: 100.07774 | E32: 1331.7702 | F32: 1702.2274 | G32: 1827.6671 | H32: =G32/E32 -> 1.3723592 | I32: 48670.683 | K32: 7.6135458 | L32: 1.5816327
A33: IST | B33: EXP | C33: varTempPressure-constSpeedMass | D33: 90.367491 | E33: 1207.5029 | F33: 1592.0281 | G33: 1740.9144 | H33: =G33/E33 -> 1.4417476 | I33: 48656.908 | K33: 9.5768924 | L33: 1.9047619 | M33: 2.3443953
A34: IST | B34: EXP | C34: varTempPressure-constSpeedMass | D34: 92.275618 | E34: 1245.0176 | F34: 1629.5428 | G34: 1777.2567 | H34: =G34/E34 -> 1.4274953 | I34: 48685.157 | K34: 9.3155378 | L34: 1.8367347 | M34: 2.2957227
A35: IST | B35: EXP | C35: varTempPressure-constSpeedMass | D35: 94.289753 | E35: 1281.3599 | F35: 1667.0574 | G35: 1812.4267 | H35: =G35/E35 -> 1.4144556 | I35: 48687.948 | K35: 9.0414343 | L35: 1.7687075 | M35: 2.2227139
A36: IST | B36: EXP | C36: varTempPressure-constSpeedMass | D36: 96.303887 | E36: 1316.5299 | F36: 1704.5721 | G36: 1846.4244 | H36: =G36/E36 -> 1.4024933 | I36: 48639.794 | K36: 8.7545817 | L36: 1.7006803 | M36: 2.1659292
A37: IST | B37: EXP | C37: varTempPressure-constSpeedMass | D37: 98.233216 | E37: 1356.3892 | F37: 1749.1208 | G37: 1887.456 | H37: =G37/E37 -> 1.3915298 | I37: 48642.616 | K37: 8.4996016 | L37: 1.6780045 | M37: 2.1253687
A38: IST | B38: EXP | C38: varTempPressure-constSpeedMass | D38: 100.28975 | E38: 1391.5592 | F38: 1787.8077 | G38: 1922.626 | H38: =G38/E38 -> 1.3816344 | I38: 48645.499 | K38: 8.250996 | L38: 1.6326531 | M38: 2.0685841
A39: IST | B39: EXP | C39: varTempPressure-constSpeedMass | D39: 102.28269 | E39: 1427.9015 | F39: 1826.4947 | G39: 1957.796 | H39: =G39/E39 -> 1.3711002 | I39: 48673.809 | K39: 8.0087649 | L39: 1.5873016 | M39: 2.0280236

Sheet notes
B2: Kimball2012 | F2: Kimball2013
B3: Knolls Atomic Power Laboratory (KAPL) | F3: Bechtel Marine Propulsion Corporation (BMPC)
B4: Bettis Atomic Power Laboratory (BAPL) | F4: Bettis Atomic Power Laboratory (BAPL)
B5: System nominal power output | C5: 100 | D5: kWe | F5: Compressor power | G5: 94 | H5: kW
B6: Heat source temperature | C6: 300 | D6: degC | F6: Compressor efficiency | G6: 60.8 | H6: %
B7: Recuperated Brayton cycle | F7: Pressure ratio | G7: 1.8 | H7: -
B8: Two-shaft arrangement (allows for a very good range of control) | F8: Windage in generator | G8: 8.1 | H8: kW
B9: Turbine + generator | F9: Drive turbine | G9: 102.2 | H9: kW
B10: Turbine + compressor | F10: Power turbine | G10: 114.9 | H10: kW
B11: The design incorporates results from Barber Nichols design for Sandia | F11: Inlet turbine temperature | G11: 300 | H11: degC
B12: Inlet temperature and pressure well above critical point to avoid two-phase operation | F12: Inlet compressor temperature | G12: 35.5 | H12: degC
B13: 100 kWe and 75000 RPM was selected as the smallest practical scale | F13: Inlet compressor pressure | G13: =9283790/100000 -> 92.8379 | H13: bar
B14: Unshrouded impeller | F14: Inlet compressor density | G14: 669.57
B15: Fixed vane diffuser (wedge diffuser) | F15: The design pressure ratio is 1.8 (the design pressure ratio for a full-scale system would be 2.5-3.5)
B16: Shaft seals and vacuum pump to reduce density and windage losses | F16: Coriolis flow meters measure mass flow rate and density
F17: Flow meters give good results for single phase and supercritical flow
B21: Performance data
B22: We have performance data corresponding to 5 test runs
B23: Each dataset name indicates what variables were varied and what variables remained constant during the run
B24: varSpeed-constTempPressure-1 | C24: Digitized fom Table 1 of 2016
B25: varSpeed-constTempPressure-2 | C25: Digitized from Figure 2 of Clementoni2021 + assumption of linspace for angular speed
B26: varPressure-constTempSpeed | C26: Digitized from Figure 2 of Clementoni2021 + additional data from Clementoni and Cox 2018
B27: varTemp-constPressureSpeed | C27: Digitized from Figure 2 of Clementoni2021 + additional data from Lewis et al 2018
B28: varTempPressure-constSpeedMass | C28: Digitized from Figure 2 of Clementoni2021 + additional data from Lewis et al 2018
B30: Mass flow data and specific work data extracted from figures 5 and 6 from Clementoni2021
B31: Digitizing the data was quite challenging because associating each marker with the corresponding operating point was not trivial
B32: Each marker was associated with the operating point based on the trend of the lines and the colors of the markers in the T-s diagram
B33: The data for mass flow rate required little to no correction due to equivalent conditions
B34: The data for the isentropic enthalpy change obtained from the figure did not match the isentropic work that I calculated from the pressure rise. Is it only impeller?
B36: Design inlet conditions for equivalent calculations
B37: p0,in | C37: 1330 | D37: psia
B38: T0,in | C38: 96 | D38: degF
B39: p0,in | C39: =C37*0.0689476 -> 91.700308 | D39: bara
B40: T0,in | C40: =(C38 - 32) * 5/9 -> 35.555556 | D40: degC
B46: Geometry from Clementoni2021
B47: Impeller wheen diameter | C47: 39.2 | D47: mm
B48: Impellet outlet blade height | C48: 2.16 | D48: mm
B49: Number of diffuser flow passages | C49: 15
B50: Diffuser area ratio | C50: 2
B55: Clementoni2014
...
